Workbook

Sheet Planilha1

Sheet Entendimento
B1: Entendimento Preliminar
B5: Unidade Auditada:
B6: N° da Base de Auditoria:
B7: Objeto da Auditoria:
B8: Coordenador:
B9: Equipe de Auditoria:
B10: Elaborado por: | F10: Data:
B11: Revisado por: | F11: Data:
B12: Supervisionado por: | F12: Data:
B14: Objetivo(s) do Objeto do Trabalho | C14: Objetivo 1
C15: Objetivo 2
C16: Objetivo 3
C17: Objetivo 4
B18: Fluxo Descritivo Mapeamento do Processo | C18: Descrever o fluxo do processo em nível de detalhe adequado aos objetivos do trabalho de auditoria e/ou anexar o mapeamento em Bizagi. Para definir o nível de detalhe, o auditor deve empregar seu julgamento profissional para evitar: - a insuficiência de informações que dão suporte ao trabalho; e - o desperdício de recursos com a obtenção de excesso de detalhes.
B19: Normativas Aplicáveis | C19: Inserir as políticas, as normas, os procedimentos e os demais regulamentos aplicáveis ao processo de negócio sob análise.
B20: Entendimento do Objeto do Trabalho | C20: Descrever de forma sintética o entendimento do auditor, obtido após seu estudo dos elementos e informações relacionados ao objeto, tais como a relevância do objeto selecionado, fluxos de processos, sistemas envolvidos, a estrutura organizacional, os responsáveis, relatórios anteriores, organogramas, políticas e normativas que regulam o objeto, processos relacionados ao objeto, entre outros, de forma que um terceiro, ao ler o entendimento, tenha uma visão dos principais componentes do objeto e seu funcionamento.

Sheet Identificação e Análise
B1: Identificação e Análise de Riscos
B7: Unidade auditada: | D7: =Entendimento!C5 -> 0
B8: Base de Auditoria: | D8: =Entendimento!C6 -> 0
B9: Elaborado por: | E9: Data:
B11: Objetivo | C11: Risco | D11: Fonte do Risco | E11: Possíveis Causas | F11: Possíveis Consequências
C12: R1 - | E12: Cs 1.1 - | F12: Cq 1.1 -
E13: Cs 1.2 - | F13: Cq 1.2 -
E14: Cs 1.3 - | F14: Cq 1.3 -
C15: R2 - | E15: Cs 2.1 - | F15: Cq 2.1 -
E16: Cs 2.2 - | F16: Cq 2.2 -
E17: Cs 2.3 - | F17: Cq 2.3 -
C18: R3 - | E18: Cs 3.1 - | F18: Cq 3.1 -
E19: Cs 3.2 - | F19: Cq 3.2 -
E20: Cs 3.3 - | F20: Cq 3.3 -
C21: R4 - | E21: Cs 4.1 - | F21: Cq 4.1 -
E22: Cs 4.2 - | F22: Cq 4.2 -
E23: Cs 4.3 - | F23: Cq 4.3 -
C24: R5 - | E24: Cs 5.1 - | F24: Cq 5.1 -
E25: Cs 5.2 - | F25: Cq 5.2 -
E26: Cs 5.3 - | F26: Cq 5.3 -
C27: R6 - | E27: Cs 6.1 - | F27: Cq 6.1 -
E28: Cs 6.2 - | F28: Cq 6.2 -
E29: Cs 6.3 - | F29: Cq 6.3 -
C30: R7 - | E30: Cs 7.1 - | F30: Cq 7.1 -
E31: Cs 7.2 - | F31: Cq 7.2 -
E32: Cs 7.3 - | F32: Cq 7.3 -
C33: R8 - | E33: Cs 8.1 - | F33: Cq 8.1 -
E34: Cs 8.2 - | F34: Cq 8.2 -
E35: Cs 8.3 - | F35: Cq 8.3 -
C36: R9 - | E36: Cs 9.1 - | F36: Cq 9.1 -
E37: Cs 9.2 - | F37: Cq 9.2 -
E38: Cs 9.3 - | F38: Cq 9.3 -

Sheet Matriz de Riscos e Controles
B1: Matriz de Riscos e Controles
B7: =Entendimento!B5 -> Unidade Auditada: | C7: =Entendimento!C5 -> 0
B8: =Entendimento!B6 -> N° da Base de Auditoria: | C8: =Entendimento!C6 -> 0
B10: Identificação dos Riscos | E10: Avaliação do Risco Inerente | K10: Avaliação Preliminar do Risco de Controle | N10: Definição de Escopo
B11: Objetivo | C11: Referência do Risco | D11: Risco | E11: Probabilidade | F11: Probabilidade (P) | G11: Impacto | H11: Impacto (I) | I11: Índice Inerente (P x I) | J11: Classificação do Risco Inerente | K11: Controles-Chave | L11: Avaliação Preliminar do Controle (Teste de Desenho) | M11: Situação do Controle | N11: Classificação do Risco Residual (Após Teste de Desenho) | O11: Síntese da Avaliação Preliminar | P11: Comentários Sobre a Avaliação Preliminar | Q11: Teste Recomendado | R11: Prioridade | S11: Conclusão do Coordenador | T11: Justificativa para incluir ou excluir risco da avaliação
B12: ='Identificação e Análise'!B12 -> 0 | C12: R1 | D12: ='Identificação e Análise'!C12 -> R1 - | F12: =VLOOKUP(Tabela1[[#This Row],[Probabilidade]],Tabelas!$B$4:$D$8,3,0) -> #N/A | H12: =VLOOKUP(Tabela1[[#This Row],[Impacto]],Tabelas!$F$4:$H$8,3,0) -> #N/A | I12: =IFERROR(H12*F12," ") | J12: =IFERROR(IF(H12*F12=0," ",IF(F12*H12<=5,Tabelas!$J$4,IF(F12*H12<=10,Tabelas!$J$5,IF(F12*H12<=15,Tabelas!$J$6,IF(F12*H12<=20,Tabelas!$J$7,IF(F12*H12=25,Tabelas!$J$8))))))," ") | M12: =IFERROR(VLOOKUP(Tabela1[[#This Row],[Avaliação Preliminar do Controle (Teste de Desenho)]],Tabelas!$N$4:$P$8,3,0),"") | N12: =IFERROR(VLOOKUP(Tabela1[[#This Row],[Classificação do Risco Inerente]]&Tabela1[[#This Row],[Avaliação Preliminar do Controle (Teste de Desenho)]],Tabelas!$X$4:$Y$28,2,0),"") | O12: =IFERROR(VLOOKUP(Tabela1[[#This Row],[Classificação do Risco Inerente]]&Tabela1[[#This Row],[Avaliação Preliminar do Controle (Teste de Desenho)]],Tabelas!$X$4:$Z$28,3,0),"") | Q12: =IFERROR(VLOOKUP(Tabela1[[#This Row],[Classificação do Risco Inerente]]&Tabela1[[#This Row],[Avaliação Preliminar do Controle (Teste de Desenho)]],Tabelas!$X$4:$AA$28,4,0),"") | R12: =IFERROR(VLOOKUP(Tabela1[[#This Row],[Classificação do Risco Inerente]]&Tabela1[[#This Row],[Avaliação Preliminar do Controle (Teste de Desenho)]],Tabelas!$X$4:$AB$28,5,0),"") | AA12: Escopo
B13: ='Identificação e Análise'!B15 -> 0 | C13: R2 | D13: ='Identificação e Análise'!C15 -> R2 - | F13: =VLOOKUP(Tabela1[[#This Row],[Probabilidade]],Tabelas!$B$4:$D$8,3,0) -> #N/A | H13: =VLOOKUP(Tabela1[[#This Row],[Impacto]],Tabelas!$F$4:$H$8,3,0) -> #N/A | I13: =IFERROR(H13*F13," ") | J13: =IFERROR(IF(H13*F13=0," ",IF(F13*H13<=5,Tabelas!$J$4,IF(F13*H13<=10,Tabelas!$J$5,IF(F13*H13<=15,Tabelas!$J$6,IF(F13*H13<=20,Tabelas!$J$7,IF(F13*H13=25,Tabelas!$J$8))))))," ") | M13: =IFERROR(VLOOKUP(Tabela1[[#This Row],[Avaliação Preliminar do Controle (Teste de Desenho)]],Tabelas!$N$4:$P$8,3,0),"") | N13: =IFERROR(VLOOKUP(Tabela1[[#This Row],[Classificação do Risco Inerente]]&Tabela1[[#This Row],[Avaliação Preliminar do Controle (Teste de Desenho)]],Tabelas!$X$4:$Y$28,2,0),"") | O13: =IFERROR(VLOOKUP(Tabela1[[#This Row],[Classificação do Risco Inerente]]&Tabela1[[#This Row],[Avaliação Preliminar do Controle (Teste de Desenho)]],Tabelas!$X$4:$Z$28,3,0),"") | Q13: =IFERROR(VLOOKUP(Tabela1[[#This Row],[Classificação do Risco Inerente]]&Tabela1[[#This Row],[Avaliação Preliminar do Controle (Teste de Desenho)]],Tabelas!$X$4:$AA$28,4,0),"") | R13: =IFERROR(VLOOKUP(Tabela1[[#This Row],[Classificação do Risco Inerente]]&Tabela1[[#This Row],[Avaliação Preliminar do Controle (Teste de Desenho)]],Tabelas!$X$4:$AB$28,5,0),"") | AA13: Não será avaliado.
B14: ='Identificação e Análise'!B18 -> 0 | C14: R3 | D14: ='Identificação e Análise'!C18 -> R3 - | F14: =VLOOKUP(Tabela1[[#This Row],[Probabilidade]],Tabelas!$B$4:$D$8,3,0) -> #N/A | H14: =VLOOKUP(Tabela1[[#This Row],[Impacto]],Tabelas!$F$4:$H$8,3,0) -> #N/A | I14: =IFERROR(H14*F14," ") | J14: =IFERROR(IF(H14*F14=0," ",IF(F14*H14<=5,Tabelas!$J$4,IF(F14*H14<=10,Tabelas!$J$5,IF(F14*H14<=15,Tabelas!$J$6,IF(F14*H14<=20,Tabelas!$J$7,IF(F14*H14=25,Tabelas!$J$8))))))," ") | M14: =IFERROR(VLOOKUP(Tabela1[[#This Row],[Avaliação Preliminar do Controle (Teste de Desenho)]],Tabelas!$N$4:$P$8,3,0),"") | N14: =IFERROR(VLOOKUP(Tabela1[[#This Row],[Classificação do Risco Inerente]]&Tabela1[[#This Row],[Avaliação Preliminar do Controle (Teste de Desenho)]],Tabelas!$X$4:$Y$28,2,0),"") | O14: =IFERROR(VLOOKUP(Tabela1[[#This Row],[Classificação do Risco Inerente]]&Tabela1[[#This Row],[Avaliação Preliminar do Controle (Teste de Desenho)]],Tabelas!$X$4:$Z$28,3,0),"") | Q14: =IFERROR(VLOOKUP(Tabela1[[#This Row],[Classificação do Risco Inerente]]&Tabela1[[#This Row],[Avaliação Preliminar do Controle (Teste de Desenho)]],Tabelas!$X$4:$AA$28,4,0),"") | R14: =IFERROR(VLOOKUP(Tabela1[[#This Row],[Classificação do Risco Inerente]]&Tabela1[[#This Row],[Avaliação Preliminar do Controle (Teste de Desenho)]],Tabelas!$X$4:$AB$28,5,0),"")
B15: ='Identificação e Análise'!B21 -> 0 | C15: R4 | D15: ='Identificação e Análise'!C21 -> R4 - | F15: =VLOOKUP(Tabela1[[#This Row],[Probabilidade]],Tabelas!$B$4:$D$8,3,0) -> #N/A | H15: =VLOOKUP(Tabela1[[#This Row],[Impacto]],Tabelas!$F$4:$H$8,3,0) -> #N/A | I15: =IFERROR(H15*F15," ") | J15: =IFERROR(IF(H15*F15=0," ",IF(F15*H15<=5,Tabelas!$J$4,IF(F15*H15<=10,Tabelas!$J$5,IF(F15*H15<=15,Tabelas!$J$6,IF(F15*H15<=20,Tabelas!$J$7,IF(F15*H15=25,Tabelas!$J$8))))))," ") | M15: =IFERROR(VLOOKUP(Tabela1[[#This Row],[Avaliação Preliminar do Controle (Teste de Desenho)]],Tabelas!$N$4:$P$8,3,0),"") | N15: =IFERROR(VLOOKUP(Tabela1[[#This Row],[Classificação do Risco Inerente]]&Tabela1[[#This Row],[Avaliação Preliminar do Controle (Teste de Desenho)]],Tabelas!$X$4:$Y$28,2,0),"") | O15: =IFERROR(VLOOKUP(Tabela1[[#This Row],[Classificação do Risco Inerente]]&Tabela1[[#This Row],[Avaliação Preliminar do Controle (Teste de Desenho)]],Tabelas!$X$4:$Z$28,3,0),"") | Q15: =IFERROR(VLOOKUP(Tabela1[[#This Row],[Classificação do Risco Inerente]]&Tabela1[[#This Row],[Avaliação Preliminar do Controle (Teste de Desenho)]],Tabelas!$X$4:$AA$28,4,0),"") | R15: =IFERROR(VLOOKUP(Tabela1[[#This Row],[Classificação do Risco Inerente]]&Tabela1[[#This Row],[Avaliação Preliminar do Controle (Teste de Desenho)]],Tabelas!$X$4:$AB$28,5,0),"")
B16: ='Identificação e Análise'!B24 -> 0 | C16: R5 | D16: ='Identificação e Análise'!C24 -> R5 - | F16: =VLOOKUP(Tabela1[[#This Row],[Probabilidade]],Tabelas!$B$4:$D$8,3,0) -> #N/A | H16: =VLOOKUP(Tabela1[[#This Row],[Impacto]],Tabelas!$F$4:$H$8,3,0) -> #N/A | I16: =IFERROR(H16*F16," ") | J16: =IFERROR(IF(H16*F16=0," ",IF(F16*H16<=5,Tabelas!$J$4,IF(F16*H16<=10,Tabelas!$J$5,IF(F16*H16<=15,Tabelas!$J$6,IF(F16*H16<=20,Tabelas!$J$7,IF(F16*H16=25,Tabelas!$J$8))))))," ") | M16: =IFERROR(VLOOKUP(Tabela1[[#This Row],[Avaliação Preliminar do Controle (Teste de Desenho)]],Tabelas!$N$4:$P$8,3,0),"") | N16: =IFERROR(VLOOKUP(Tabela1[[#This Row],[Classificação do Risco Inerente]]&Tabela1[[#This Row],[Avaliação Preliminar do Controle (Teste de Desenho)]],Tabelas!$X$4:$Y$28,2,0),"") | O16: =IFERROR(VLOOKUP(Tabela1[[#This Row],[Classificação do Risco Inerente]]&Tabela1[[#This Row],[Avaliação Preliminar do Controle (Teste de Desenho)]],Tabelas!$X$4:$Z$28,3,0),"") | Q16: =IFERROR(VLOOKUP(Tabela1[[#This Row],[Classificação do Risco Inerente]]&Tabela1[[#This Row],[Avaliação Preliminar do Controle (Teste de Desenho)]],Tabelas!$X$4:$AA$28,4,0),"") | R16: =IFERROR(VLOOKUP(Tabela1[[#This Row],[Classificação do Risco Inerente]]&Tabela1[[#This Row],[Avaliação Preliminar do Controle (Teste de Desenho)]],Tabelas!$X$4:$AB$28,5,0),"")
B17: ='Identificação e Análise'!B27 -> 0 | C17: R6 | D17: ='Identificação e Análise'!C27 -> R6 - | F17: =VLOOKUP(Tabela1[[#This Row],[Probabilidade]],Tabelas!$B$4:$D$8,3,0) -> #N/A | H17: =VLOOKUP(Tabela1[[#This Row],[Impacto]],Tabelas!$F$4:$H$8,3,0) -> #N/A | I17: =IFERROR(H17*F17," ") | J17: =IFERROR(IF(H17*F17=0," ",IF(F17*H17<=5,Tabelas!$J$4,IF(F17*H17<=10,Tabelas!$J$5,IF(F17*H17<=15,Tabelas!$J$6,IF(F17*H17<=20,Tabelas!$J$7,IF(F17*H17=25,Tabelas!$J$8))))))," ") | M17: =IFERROR(VLOOKUP(Tabela1[[#This Row],[Avaliação Preliminar do Controle (Teste de Desenho)]],Tabelas!$N$4:$P$8,3,0),"") | N17: =IFERROR(VLOOKUP(Tabela1[[#This Row],[Classificação do Risco Inerente]]&Tabela1[[#This Row],[Avaliação Preliminar do Controle (Teste de Desenho)]],Tabelas!$X$4:$Y$28,2,0),"") | O17: =IFERROR(VLOOKUP(Tabela1[[#This Row],[Classificação do Risco Inerente]]&Tabela1[[#This Row],[Avaliação Preliminar do Controle (Teste de Desenho)]],Tabelas!$X$4:$Z$28,3,0),"") | Q17: =IFERROR(VLOOKUP(Tabela1[[#This Row],[Classificação do Risco Inerente]]&Tabela1[[#This Row],[Avaliação Preliminar do Controle (Teste de Desenho)]],Tabelas!$X$4:$AA$28,4,0),"") | R17: =IFERROR(VLOOKUP(Tabela1[[#This Row],[Classificação do Risco Inerente]]&Tabela1[[#This Row],[Avaliação Preliminar do Controle (Teste de Desenho)]],Tabelas!$X$4:$AB$28,5,0),"")
B18: ='Identificação e Análise'!B30 -> 0 | C18: R7 | D18: ='Identificação e Análise'!C30 -> R7 - | F18: =VLOOKUP(Tabela1[[#This Row],[Probabilidade]],Tabelas!$B$4:$D$8,3,0) -> #N/A | H18: =VLOOKUP(Tabela1[[#This Row],[Impacto]],Tabelas!$F$4:$H$8,3,0) -> #N/A | I18: =IFERROR(H18*F18," ") | J18: =IFERROR(IF(H18*F18=0," ",IF(F18*H18<=5,Tabelas!$J$4,IF(F18*H18<=10,Tabelas!$J$5,IF(F18*H18<=15,Tabelas!$J$6,IF(F18*H18<=20,Tabelas!$J$7,IF(F18*H18=25,Tabelas!$J$8))))))," ") | M18: =IFERROR(VLOOKUP(Tabela1[[#This Row],[Avaliação Preliminar do Controle (Teste de Desenho)]],Tabelas!$N$4:$P$8,3,0),"") | N18: =IFERROR(VLOOKUP(Tabela1[[#This Row],[Classificação do Risco Inerente]]&Tabela1[[#This Row],[Avaliação Preliminar do Controle (Teste de Desenho)]],Tabelas!$X$4:$Y$28,2,0),"") | O18: =IFERROR(VLOOKUP(Tabela1[[#This Row],[Classificação do Risco Inerente]]&Tabela1[[#This Row],[Avaliação Preliminar do Controle (Teste de Desenho)]],Tabelas!$X$4:$Z$28,3,0),"") | Q18: =IFERROR(VLOOKUP(Tabela1[[#This Row],[Classificação do Risco Inerente]]&Tabela1[[#This Row],[Avaliação Preliminar do Controle (Teste de Desenho)]],Tabelas!$X$4:$AA$28,4,0),"") | R18: =IFERROR(VLOOKUP(Tabela1[[#This Row],[Classificação do Risco Inerente]]&Tabela1[[#This Row],[Avaliação Preliminar do Controle (Teste de Desenho)]],Tabelas!$X$4:$AB$28,5,0),"")
B19: ='Identificação e Análise'!B33 -> 0 | C19: R8 | D19: ='Identificação e Análise'!C33 -> R8 - | F19: =VLOOKUP(Tabela1[[#This Row],[Probabilidade]],Tabelas!$B$4:$D$8,3,0) -> #N/A | H19: =VLOOKUP(Tabela1[[#This Row],[Impacto]],Tabelas!$F$4:$H$8,3,0) -> #N/A | I19: =IFERROR(H19*F19," ") | J19: =IFERROR(IF(H19*F19=0," ",IF(F19*H19<=5,Tabelas!$J$4,IF(F19*H19<=10,Tabelas!$J$5,IF(F19*H19<=15,Tabelas!$J$6,IF(F19*H19<=20,Tabelas!$J$7,IF(F19*H19=25,Tabelas!$J$8))))))," ") | M19: =IFERROR(VLOOKUP(Tabela1[[#This Row],[Avaliação Preliminar do Controle (Teste de Desenho)]],Tabelas!$N$4:$P$8,3,0),"") | N19: =IFERROR(VLOOKUP(Tabela1[[#This Row],[Classificação do Risco Inerente]]&Tabela1[[#This Row],[Avaliação Preliminar do Controle (Teste de Desenho)]],Tabelas!$X$4:$Y$28,2,0),"") | O19: =IFERROR(VLOOKUP(Tabela1[[#This Row],[Classificação do Risco Inerente]]&Tabela1[[#This Row],[Avaliação Preliminar do Controle (Teste de Desenho)]],Tabelas!$X$4:$Z$28,3,0),"") | Q19: =IFERROR(VLOOKUP(Tabela1[[#This Row],[Classificação do Risco Inerente]]&Tabela1[[#This Row],[Avaliação Preliminar do Controle (Teste de Desenho)]],Tabelas!$X$4:$AA$28,4,0),"") | R19: =IFERROR(VLOOKUP(Tabela1[[#This Row],[Classificação do Risco Inerente]]&Tabela1[[#This Row],[Avaliação Preliminar do Controle (Teste de Desenho)]],Tabelas!$X$4:$AB$28,5,0),"")
B20: ='Identificação e Análise'!B36 -> 0 | C20: R9 | D20: ='Identificação e Análise'!C36 -> R9 - | F20: =VLOOKUP(Tabela1[[#This Row],[Probabilidade]],Tabelas!$B$4:$D$8,3,0) -> #N/A | H20: =VLOOKUP(Tabela1[[#This Row],[Impacto]],Tabelas!$F$4:$H$8,3,0) -> #N/A | I20: =IFERROR(H20*F20," ") | J20: =IFERROR(IF(H20*F20=0," ",IF(F20*H20<=5,Tabelas!$J$4,IF(F20*H20<=10,Tabelas!$J$5,IF(F20*H20<=15,Tabelas!$J$6,IF(F20*H20<=20,Tabelas!$J$7,IF(F20*H20=25,Tabelas!$J$8))))))," ") | M20: =IFERROR(VLOOKUP(Tabela1[[#This Row],[Avaliação Preliminar do Controle (Teste de Desenho)]],Tabelas!$N$4:$P$8,3,0),"") | N20: =IFERROR(VLOOKUP(Tabela1[[#This Row],[Classificação do Risco Inerente]]&Tabela1[[#This Row],[Avaliação Preliminar do Controle (Teste de Desenho)]],Tabelas!$X$4:$Y$28,2,0),"") | O20: =IFERROR(VLOOKUP(Tabela1[[#This Row],[Classificação do Risco Inerente]]&Tabela1[[#This Row],[Avaliação Preliminar do Controle (Teste de Desenho)]],Tabelas!$X$4:$Z$28,3,0),"") | Q20: =IFERROR(VLOOKUP(Tabela1[[#This Row],[Classificação do Risco Inerente]]&Tabela1[[#This Row],[Avaliação Preliminar do Controle (Teste de Desenho)]],Tabelas!$X$4:$AA$28,4,0),"") | R20: =IFERROR(VLOOKUP(Tabela1[[#This Row],[Classificação do Risco Inerente]]&Tabela1[[#This Row],[Avaliação Preliminar do Controle (Teste de Desenho)]],Tabelas!$X$4:$AB$28,5,0),"")
J25: CRÍTICO
J26: ALTO
J27: MODERADO
J28: BAIXO
J29: IRRELEVANTE

Sheet Mapa de Calor
A3: IMPACTO | B3: Crítico | C3: 10 | D3: =$C3*D8 -> 10 | E3: =$C3*E8 -> 30 | F3: =$C3*F8 -> 50 | G3: =$C3*G8 -> 80 | H3: =$C3*H8 -> 100
B4: Alto | C4: 8 | D4: =$C4*D8 -> 8 | E4: =$C4*E8 -> 24 | F4: =$C4*F8 -> 40 | G4: =$C4*G8 -> 64 | H4: =$C4*H8 -> 80
B5: Moderado | C5: 5 | D5: =$C$4*D8 -> 8 | E5: =$C$4*E8 -> 24 | F5: =$C$4*F8 -> 40 | G5: =$C$4*G8 -> 64 | H5: =$C$4*H8 -> 80
B6: Baixo | C6: 3 | D6: =$C$5*D8 -> 5 | E6: =$C$5*E8 -> 15 | F6: =$C$5*F8 -> 25 | G6: =$C$5*G8 -> 40 | H6: =$C$5*H8 -> 50
B7: Irrelevante | C7: 1 | D7: =$C$6*D8 -> 3 | E7: =$C$6*E8 -> 9 | F7: =$C$6*F8 -> 15 | G7: =$C$6*G8 -> 24 | H7: =$C$6*H8 -> 30
D8: 1 | E8: 3 | F8: 5 | G8: 8 | H8: 10
D9: Raro | E9: Improvável | F9: Possível | G9: Provável | H9: Esperado
D10: PROBABILIDADE

Sheet Matriz de Planejamento
B1: Matriz de Planejamento
B6: =Entendimento!B5 -> Unidade Auditada: | C6: =Entendimento!C5 -> 0
B7: =Entendimento!B6 -> N° da Base de Auditoria: | C7: =Entendimento!C6 -> 0
B8: Elaborado por: | F8: Data:
B10: Questão Geral de Auditoria
B11: Risco | C11: Referência da Subquestão | D11: Subquestão de Auditoria | E11: Critério | F11: Procedimentos de Auditoria | G11: Programa de Trabalho
C12: 1.1 | G12: PT1.1
C13: 1.2 | G13: PT1.2
C14: 1.3
C15: 1.4
C16: 1.5
C17: 1.6
C18: 1.7
C19: 1.8
C20: 1.n
B21: Resposta à Questão Geral de Auditoria

Sheet Matriz de Achados(1)
B1: Matriz de Achados
B4: Entidade auditada: | C4: =Entendimento!C5 -> 0
B6: Base de auditoria: | C6: =Entendimento!C6 -> 0
B8: Elaborado por: | J8: Data:
B10: Revisado por: | J10: Data:
B12: =Entendimento!#REF! -> #REF! | C12: =Entendimento!#REF! -> #REF!
B14: =Entendimento!B14 -> Objetivo(s) do Objeto do Trabalho | C14: =Entendimento!C17 -> Objetivo 4
B16: Questão de Auditoria | C16: =Entendimento!#REF! -> #REF!
B18: Risco | C18: Causa (s) | D18: Consequência (s) | E18: Subquestão | F18: Critério (s) | G18: Situação Encontrada | H18: Conclusão Final | I18: Recomendação | J18: Benefìcio Esperado | K18: Observações do Revisor
B20: ='Matriz de Planejamento'!B12 -> 0 | C20: =VLOOKUP(B20,'Identificação e Análise'!C12:F38,4,0) -> #N/A | D20: =VLOOKUP(B20,'Identificação e Análise'!C12:F38,6,0) -> #N/A | E20: =VLOOKUP(B20,Tabela20[[Risco]:[Referência da Subquestão]],4,0) -> #N/A | F20: =VLOOKUP(B20,#REF!,3,0) -> #REF! | G20: =VLOOKUP(B20,#REF!,7,0) -> #REF! | H20: =VLOOKUP(B20,#REF!,8,0) -> #REF! | I20: =VLOOKUP(B20,#REF!,9,0) -> #REF! | J20: =VLOOKUP(B20,#REF!,10,0) -> #REF!
B21: ='Matriz de Planejamento'!B13 -> 0 | C21: =VLOOKUP(B21,'Identificação e Análise'!C15:F42,4,0) -> #N/A | D21: =VLOOKUP(B21,'Identificação e Análise'!C15:F42,6,0) -> #N/A | E21: =VLOOKUP(B21,Tabela20[[Risco]:[Referência da Subquestão]],4,0) -> #N/A | F21: =VLOOKUP(B21,#REF!,3,0) -> #REF! | G21: =VLOOKUP(B21,#REF!,7,0) -> #REF! | H21: =VLOOKUP(B21,#REF!,8,0) -> #REF! | I21: =VLOOKUP(B21,#REF!,9,0) -> #REF! | J21: =VLOOKUP(B21,#REF!,10,0) -> #REF!
B22: ='Matriz de Planejamento'!B14 -> 0 | C22: =VLOOKUP(B22,'Identificação e Análise'!C18:F43,4,0) -> #N/A | D22: =VLOOKUP(B22,'Identificação e Análise'!C18:F43,6,0) -> #N/A | E22: =VLOOKUP(B22,Tabela20[[Risco]:[Referência da Subquestão]],4,0) -> #N/A | F22: =VLOOKUP(B22,#REF!,3,0) -> #REF! | G22: =VLOOKUP(B22,#REF!,7,0) -> #REF! | H22: =VLOOKUP(B22,#REF!,8,0) -> #REF! | I22: =VLOOKUP(B22,#REF!,9,0) -> #REF! | J22: =VLOOKUP(B22,#REF!,10,0) -> #REF!
B23: ='Matriz de Planejamento'!B15 -> 0 | C23: =VLOOKUP(B23,'Identificação e Análise'!C21:F43,4,0) -> #N/A | D23: =VLOOKUP(B23,'Identificação e Análise'!C21:F43,6,0) -> #N/A | E23: =VLOOKUP(B23,Tabela20[[Risco]:[Referência da Subquestão]],4,0) -> #N/A | F23: =VLOOKUP(B23,#REF!,3,0) -> #REF! | G23: =VLOOKUP(B23,#REF!,7,0) -> #REF! | H23: =VLOOKUP(B23,#REF!,8,0) -> #REF! | I23: =VLOOKUP(B23,#REF!,9,0) -> #REF! | J23: =VLOOKUP(B23,#REF!,10,0) -> #REF!
B24: ='Matriz de Planejamento'!B16 -> 0 | C24: =VLOOKUP(B24,'Identificação e Análise'!C24:F43,4,0) -> #N/A | D24: =VLOOKUP(B24,'Identificação e Análise'!C24:F43,6,0) -> #N/A | E24: =VLOOKUP(B24,Tabela20[[Risco]:[Referência da Subquestão]],4,0) -> #N/A | F24: =VLOOKUP(B24,#REF!,3,0) -> #REF! | G24: =VLOOKUP(B24,#REF!,7,0) -> #REF! | H24: =VLOOKUP(B24,#REF!,8,0) -> #REF! | I24: =VLOOKUP(B24,#REF!,9,0) -> #REF! | J24: =VLOOKUP(B24,#REF!,10,0) -> #REF!
B25: ='Matriz de Planejamento'!B17 -> 0 | C25: =VLOOKUP(B25,'Identificação e Análise'!C27:F43,4,0) -> #N/A | D25: =VLOOKUP(B25,'Identificação e Análise'!C27:F43,6,0) -> #N/A | E25: =VLOOKUP(B25,Tabela20[[Risco]:[Referência da Subquestão]],4,0) -> #N/A | F25: =VLOOKUP(B25,#REF!,3,0) -> #REF! | G25: =VLOOKUP(B25,#REF!,7,0) -> #REF! | H25: =VLOOKUP(B25,#REF!,8,0) -> #REF! | I25: =VLOOKUP(B25,#REF!,9,0) -> #REF! | J25: =VLOOKUP(B25,#REF!,10,0) -> #REF!
B26: ='Matriz de Planejamento'!B18 -> 0 | C26: =VLOOKUP(B26,'Identificação e Análise'!C30:F43,4,0) -> #N/A | D26: =VLOOKUP(B26,'Identificação e Análise'!C30:F43,6,0) -> #N/A | E26: =VLOOKUP(B26,Tabela20[[Risco]:[Referência da Subquestão]],4,0) -> #N/A | F26: =VLOOKUP(B26,#REF!,3,0) -> #REF! | G26: =VLOOKUP(B26,#REF!,7,0) -> #REF! | H26: =VLOOKUP(B26,#REF!,8,0) -> #REF! | I26: =VLOOKUP(B26,#REF!,9,0) -> #REF! | J26: =VLOOKUP(B26,#REF!,10,0) -> #REF!
B27: ='Matriz de Planejamento'!B19 -> 0 | C27: =VLOOKUP(B27,'Identificação e Análise'!C33:F43,4,0) -> #N/A | D27: =VLOOKUP(B27,'Identificação e Análise'!C33:F43,6,0) -> #N/A | E27: =VLOOKUP(B27,Tabela20[[Risco]:[Referência da Subquestão]],4,0) -> #N/A | F27: =VLOOKUP(B27,#REF!,3,0) -> #REF! | G27: =VLOOKUP(B27,#REF!,7,0) -> #REF! | H27: =VLOOKUP(B27,#REF!,8,0) -> #REF! | I27: =VLOOKUP(B27,#REF!,9,0) -> #REF! | J27: =VLOOKUP(B27,#REF!,10,0) -> #REF!
B28: ='Matriz de Planejamento'!B20 -> 0 | C28: =VLOOKUP(B28,'Identificação e Análise'!C36:F43,4,0) -> #N/A | D28: =VLOOKUP(B28,'Identificação e Análise'!C36:F43,6,0) -> #N/A | E28: =VLOOKUP(B28,Tabela20[[Risco]:[Referência da Subquestão]],4,0) -> #N/A | F28: =VLOOKUP(B28,#REF!,3,0) -> #REF! | G28: =VLOOKUP(B28,#REF!,7,0) -> #REF! | H28: =VLOOKUP(B28,#REF!,8,0) -> #REF! | I28: =VLOOKUP(B28,#REF!,9,0) -> #REF! | J28: =VLOOKUP(B28,#REF!,10,0) -> #REF!

Sheet Matriz de Referência
B1: Matriz de Achados
B4: Entidade auditada: | C4: =Entendimento!C5 -> 0
B6: Base de auditoria: | C6: =Entendimento!C6 -> 0
B8: Elaborado por: | H8: Data:
B10: Revisado por: | H10: Data:
B12: =Entendimento!#REF! -> #REF! | C12: =Entendimento!#REF! -> #REF!
B14: =Entendimento!B14 -> Objetivo(s) do Objeto do Trabalho | C14: =Entendimento!C17 -> Objetivo 4
B16: Questão de Auditoria | C16: =Entendimento!#REF! -> #REF!
J17: Insatisfatório
B18: Subquestão | C18: Risco | D18: Causa (s) | E18: Consequência (s) | F18: Critério (s) | G18: Situação Encontrada | H18: Recomendação | I18: Benefìcio Esperado | J18: Observações do Revisor
B20: {=_xlfn._xlws.FILTER('Matriz de Achados(1)'!C20:C28,'Matriz de Referência'!$J$17='Matriz de Achados(1)'!$H$20:$H$28)} -> #REF! | C20: {=_xlfn._xlws.FILTER('Matriz de Achados(1)'!D20:D28,'Matriz de Referência'!$J$17='Matriz de Achados(1)'!$H$20:$H$28)} -> #REF! | D20: {=_xlfn._xlws.FILTER('Matriz de Achados(1)'!E20:E28,'Matriz de Referência'!$J$17='Matriz de Achados(1)'!$H$20:$H$28)} -> #REF! | E20: {=_xlfn._xlws.FILTER('Matriz de Achados(1)'!F20:F28,'Matriz de Referência'!$J$17='Matriz de Achados(1)'!$H$20:$H$28)} -> #REF! | F20: {=_xlfn._xlws.FILTER('Matriz de Achados(1)'!G20:G28,'Matriz de Referência'!$J$17='Matriz de Achados(1)'!$H$20:$H$28)} -> #REF! | G20: {=_xlfn._xlws.FILTER('Matriz de Achados(1)'!H20:H40,'Matriz de Referência'!$J$17='Matriz de Achados(1)'!$H$20:$H$40)} -> #REF! | H20: {=_xlfn._xlws.FILTER('Matriz de Achados(1)'!I20:I28,'Matriz de Referência'!$J$17='Matriz de Achados(1)'!$H$20:$H$28)} -> #REF! | I20: {=_xlfn._xlws.FILTER('Matriz de Achados(1)'!J20:J28,'Matriz de Referência'!$J$17='Matriz de Achados(1)'!$H$20:$H$28)} -> #REF!

Sheet Listas
B2: Unidades Auditadas | D2: Supervisores | F2: Coordenadores | H2: Auditores | J2: Conclusão da avaliação | L2: Status da Execução
B3: Agência Estadual de Regulação dos Serviços Públicos Delegados do RS - AGERGS | D3: Guilherme Pinto de Lima | F3: Alexandre Silva de Castro | H3: Alécio José Vargas | J3: Satisfatório | L3: Não Iniciado
B4: BADESUL Desenvolvimento S.A. - Agência de Fomento/RS | D4: Luis Felipe Pacheco | F4: Catherine Kaori Makiyama | H4: Alexandre Silva de Castro | J4: Insatisfatório | L4: Em execução
B5: Banco do Estado do Rio Grande do Sul S.A. - BANRISUL | D5: Thomaz Menna Barreto Moojen | F5: Fernanda Mallmann | H5: Bruno Dias Pereira | J5: Inconclusivo | L5: Concluído
B6: Brigada Militar | F6: Gabriela Marin Konzen Balbinot | H6: Carlos Yuji Nagayama | J6: Não Aplicável
B7: Banco Regional de Desenvolvimento do Extremo Sul - BRDE | F7: Rodrigo Moreira Machado | H7: Catherine Kaori Makiyama
B8: Caixa de Administração da Dívida Pública Estadual S.A. - CADIP | F8: Luis André Cabral de Carvalho | H8: Cleber Ferreira de Lima
B9: Corpo de Bombeiros Militar RS | F9: Paulo Roberto Nunes Ferreira | H9: Diego de Souza Mendonça
B10: Centrais de Abastecimento do Rio Grande do Sul S.A. - CEASA | F10: Rafael Rosenfeld | H10: Dione Silva Santos
B11: Companhia Riograndense de Mineração - CRM | F11: Renata Bartzen Pereira | H11: Fernanda Mallmann
B12: Companhia Operadora de Mineração - COM | H12: Francisco Estevanes Peres
B13: Departamento Autônomo de Estradas de Rodagem - DAER | H13: Francisco Gomes
B14: Departamento Estadual de Trânsito do RS - DETRAN | H14: Gabriela Marin Konzen Balbinot
B15: Defensoria Pública do Estado - DPE | H15: Guilherme Pinto de Lima
B16: Escritório de Desenvolvimento de Projetos - EDP | H16: Jairo Berleza Guerra
B17: Empresa Gaúcha de Rodovias S/A - EGR | H17: Jefferson Douglas dos Santos Passos
B18: Fundação de Articulação e Desenvolvimento de Políticas Públicas P/Pessoas Portadoras de Deficiência e de Altas Habilidades no RS - FADERS | H18: Jorge Luis Letner dos Santos
B19: Fundação de Amparo à Pesquisa do Estado do Rio Grande do Sul - FAPERGS | H19: Juan Marcelo Schenkel Rivera
B20: Fundação de Atendimento Sócio-Educativo - FASE | H20: Lorenzo Giacomo Venzon
B21: Fundação Estadual de Proteção Ambiental Henrique Luís Roessler - FEPAM | H21: Luis André Cabral de Carvalho
B22: Fundação Escola Técnica Liberato Salzano Vieira da Cunha - FETLSVC | H22: Luis Felipe Pacheco
B23: Fundação Gaúcha do Trabalho e Ação Social - FGTAS | H23: Marcos de Oliveira Ramos
... B35: Fundação de Previdência Complementar do Servidor Público do Estado do Rio Grande do Sul - RS-PREV | H35: Thomaz Menna Barreto Moojen
B36: Superintendência dos Serviços Penitenciários - SSP
B37: Universidade Estadual do RS - UERGS
B38: Governador do Estado RS
B39: Secretário-Chefe da Casa Civil
B40: Casa Militar
B41: Procuradoria Geral do Estado - PGE/RS
B42: Assembleia Legislativa do Estado do RS - ALRS
B43: Tribunal de Contas do Estado do RS - TCE/RS
B44: Secretaria do Meio Ambiente e Infraestrutura - SEMA
B45: Secretaria da Agricultura, Pecuária, Produção Sustentável e Irrigação - SEAPI
B46: Secretaria da Educação - SEDUC
B47: Secretaria da Fazenda - SEFAZ
... B69: Secretaria de Turismo - SETUR

Sheet Tabelas
B2: Probabilidade | F2: Impacto | J2: Nível de Risco Inerente (RI) | M2: Nível de Confiança no Controle (RC) | S2: Nível de Risco Residual (RR) | V2: Quadro auxiliar para definição dos Tipos de Testes
B3: Classificação | C3: Descrição | D3: Pontuação | F3: Classificação | G3: Descrição | H3: Pontuação | J3: Classificação | K3: Pontuação | M3: Pontuação | N3: Avaliação Preliminar | O3: Funcionamento | P3: Descrição | Q3: Teste recomendado | S3: Classificação | T3: Pontuação | V3: Risco inerente | W3: Avaliação preliminar do Controle | Y3: Risco Residual | Z3: Comentário | AA3: Tipo de Teste | AB3: Prioridade
B4: Raro | C4: Excepcionalmente poderá até ocorrer, porém não há elementos ou informações que indiquem essa possibilidade. | D4: 1 | F4: Irrelevante | G4: Degradação de operações ou atividades de processos, projetos ou programas da organização, porém causando impactos mínimos nos objetivos de prazo, custo, qualidade, escopo, imagem ou relacionados ao atendimento de metas, padrões ou à capacidade de entrega de produtos/serviços às partes interessadas (clientes internos/externos, beneficiários). | H4: 1 | J4: Irrelevante | K4: De 1 a 5 | M4: 5 | N4: Forte | O4: Efetivo | P4: O controle funciona adequadamente. Controle institucionalizado e sustentado por ferramentas adequadas, podendo ser considerado em um nível de "melhor prática"; mitiga o risco em todos os aspectos relevantes. | Q4: Testes de controle | S4: Irrelevante | T4: De 1 a 5 | V4: Irrelevante | W4: =$N$8 -> Inexistente | X4: =V4&W4 -> IrrelevanteInexistente | Y4: Insignificante | Z4: Considerando o princípio da eficiência e a relação custo-benefício, não é justificável trabalhar estes riscos. | AA4: Realizar testes apenas se o auditor julgar necessário | AB4: Mínima
B5: Improvável | C5: O evento poderá ocorrer de forma inesperada, havendo poucos elementos ou informações que indicam essa possibilidade, ou repete-se com baixa frequência anual. | D5: 2 | F5: Baixo | G5: Degradação de operações ou atividades de processos, projetos ou programas da organização, causando impactos pequenos nos objetivos. | H5: 2 | J5: Baixo | K5: De 6 a 10 | M5: 4 | N5: Satisfatório | O5: Necessita de pequenas melhorias | P5: O controle apresenta pequenas inconsistências. Controle institucionalizado e embora passível de aperfeiçoamento, é sustentado por ferramentas adequadas e mitiga o risco razoavelmente. | Q5: Testes de controle | S5: Baixo | T5: De 6 a 10 | V5: Irrelevante | W5: =$N$7 -> Fraco | X5: =V5&W5 -> IrrelevanteFraco | Y5: Insignificante | Z5: Considerando o princípio da eficiência e a relação custo-benefício, não é justificável trabalhar estes riscos. | AA5: Realizar testes apenas se o auditor julgar necessário | AB5: Mínima
B6: Possível | C6: Há elementos e/ou informações que indicam moderadamente essa possibilidade, ou repete-se com razoável frequência anual | D6: 3 | F6: Moderado | G6: Interrupção de operações ou atividades de processos, projetos ou programas, causando impactos significativos nos objetivos, porém recuperáveis. | H6: 3 | J6: Moderado | K6: De 12 a 15 | M6: 3 | N6: Mediano | O6: Necessita de grandes melhorias | P6: O controle apresenta inconsistências. Controle razoavelmente institucionalizado, mas pode falhar por não contemplar todos os aspectos relevantes do risco ou porque seu desenho ou as ferramentas que o suportam não são adequados. | Q6: Testes substantivos/Testes de Controles | S6: Moderado | T6: De 12 a 15 | V6: Irrelevante | W6: =$N$6 -> Mediano | X6: =V6&W6 -> IrrelevanteMediano | Y6: Insignificante | Z6: Considerando o princípio da eficiência e a relação custo-benefício, não é justificável trabalhar estes riscos. | AA6: Realizar testes apenas se o auditor julgar necessário | AB6: Mínima
B7: Provável | C7: É esperado que o evento ocorra, pois os elementos e as informações disponíveis indicam de forma consistente essa possibilidade, ou repete-se com elevada frequência anual. | D7: 4 | F7: Alto | G7: Interrupção de operações ou atividades de processos, projetos ou programas da organização, causando impactos de reversão muito difícil nos objetivos. | H7: 4 | J7: Alto | K7: De 16 a 20 | M7: 2 | N7: Fraco | O7: Necessita ser redesenhado | P7: O controle apresenta grandes inconsistências. Controle não institucionalizado; está na esfera de conhecimento pessoal dos operadores do processo; em geral realizado de maneira manual. | Q7: Testes substantivos | S7: Alto | T7: De 16 a 20 | V7: Irrelevante | W7: =$N$5 -> Satisfatório | X7: =V7&W7 -> IrrelevanteSatisfatório | Y7: Insignificante | Z7: Considerando o princípio da eficiência e a relação custo-benefício, não é justificável trabalhar estes riscos. | AA7: Realizar testes apenas se o auditor julgar necessário | AB7: Mínima
B8: Esperado | C8: Inequivocamente o evento ocorrerá, pois os elementos e informações disponíveis indicam claramente essa possibilidade | D8: 5 | F8: Crítico | G8: Paralisação de operações ou atividades de processos, projetos ou programas da organização, causando impactos irreversíveis/catastróficos nos objetivos. | H8: 5 | J8: Crítico | K8: De 21 a 25 | M8: 1 | N8: Inexistente | O8: Necessário desenvolver | P8: Controle não existe, não funciona ou não está implementado. | Q8: Testes substantivos | S8: Crítico | T8: De 21 a 25 | V8: Irrelevante | W8: =$N$4 -> Forte | X8: =V8&W8 -> IrrelevanteForte | Y8: Insignificante | Z8: Considerando o princípio da eficiência e a relação custo-benefício, não é justificável trabalhar estes riscos. | AA8: Realizar testes apenas se o auditor julgar necessário | AB8: Mínima
B9: Fonte: Brasil. Tribunal de Contas da União. Roteiro de Auditoria de Gestão de Riscos. | M9: * Não há controle perfeito. Todos têm limitações que impedem que NC seja igual a 1 (um). Por isto, não há RC < 0,20. Limitações do controle: relação custo-benefício; burla pela administração; conluio; erros de julgamento; falha humana (causada por fadiga, doença...); eventos externos. | V9: Baixo | W9: =$N$8 -> Inexistente | X9: =V9&W9 -> BaixoInexistente | Y9: Baixo | Z9: Considerando o princípio da eficiência e a relação custo-benefício, não seria necessário trabalhar estes riscos, por serem baixos. Entretanto, eles poderão ser testados a depender da avaliação do auditor. | AA9: Realizar testes apenas se o auditor julgar necessário | AB9: Muito baixa
B10: Brasília: TCU, Secretaria de Métodos e Suporte ao Controle Externo, 2017. (adaptada) | V10: Baixo | W10: =$N$7 -> Fraco | X10: =V10&W10 -> BaixoFraco | Y10: Baixo | Z10: Considerando o princípio da eficiência e a relação custo-benefício, não seria necessário trabalhar estes riscos, por serem baixos. Entretanto, eles poderão ser testados a depender da avaliação do auditor. | AA10: Realizar testes apenas se o auditor julgar necessário | AB10: Muito baixa
V11: Baixo | W11: =$N$6 -> Mediano | X11: =V11&W11 -> BaixoMediano | Y11: Baixo | Z11: Considerando o princípio da eficiência e a relação custo-benefício, não seria necessário trabalhar estes riscos, por serem baixos. Entretanto, eles poderão ser testados a depender da avaliação do auditor. | AA11: Realizar testes apenas se o auditor julgar necessário | AB11: Muito baixa
V12: Baixo | W12: =$N$5 -> Satisfatório | X12: =V12&W12 -> BaixoSatisfatório | Y12: Baixo | Z12: Considerando o princípio da eficiência e a relação custo-benefício, não seria necessário trabalhar estes riscos, por serem baixos. Entretanto, eles poderão ser testados a depender da avaliação do auditor. | AA12: Realizar testes apenas se o auditor julgar necessário | AB12: Muito baixa
V13: Baixo | W13: =$N$4 -> Forte | X13: =V13&W13 -> BaixoForte | Y13: Baixo | Z13: Considerando o princípio da eficiência e a relação custo-benefício, não seria necessário trabalhar estes riscos, por serem baixos. Entretanto, eles poderão ser testados a depender da avaliação do auditor. | AA13: Realizar testes apenas se o auditor julgar necessário | AB13: Muito baixa
V14: Moderado | W14: =$N$8 -> Inexistente | X14: =V14&W14 -> ModeradoInexistente | Y14: Médio | Z14: Controle inexiste. O exame poderá ser feito para confirmar consequências adversas da ausência do controle. | AA14: Testes substantivos | AB14: Alta
V15: Moderado | W15: =$N$7 -> Fraco | X15: =V15&W15 -> ModeradoFraco | Y15: Baixo/Médio | Z15: Controle foi considerado inadequado. O exame poderá ser feito para confirmar consequências adversas da inadequação. | AA15: +Testes substantivos | AB15: Alta, dependerá do nível dos riscos que o controle pretende mitigar
V16: Moderado | W16: =$N$6 -> Mediano | X16: =V16&W16 -> ModeradoMediano | Y16: Baixo/Médio | Z16: Sua aplicação/efetividade pode ser testada, para verificar seu desempenho em relação aos objetivos pretendidos, ao mesmo tempo em que é preciso confirmar as consequências adversas de seu funcionamento não ser o ideal. | AA16: Testes substantivos/Testes de Controles | AB16: Alta, dependerá do nível dos riscos que o controle pretende mitigar
V17: Moderado | W17: =$N$5 -> Satisfatório | X17: =V17&W17 -> ModeradoSatisfatório | Y17: Baixo/Médio | Z17: Controle foi considerado adequado na avaliação preliminar, mas sua aplicação/efetividade precisa ser testada, para verificar se está atingindo os objetivos pretendidos. | AA17: Testes substantivos/Testes de Controles | AB17: Baixa
V18: Moderado | W18: =$N$4 -> Forte | X18: =V18&W18 -> ModeradoForte | Y18: Baixo | Z18: Controle foi considerado forte na avaliação preliminar, mas sua aplicação/efetividade precisa ser testada, para verificar se está atingindo os objetivos pretendidos. | AA18: Testes substantivos/Testes de Controles | AB18: Baixa
V19: Alto | W19: =$N$8 -> Inexistente | X19: =V19&W19 -> AltoInexistente | Y19: Alto | Z19: Controle inexiste. O exame poderá ser feito para confirmar consequências adversas da inadequação ou ausência do controle. | AA19: Testes substantivos | AB19: Muito alta
V20: Alto | W20: =$N$7 -> Fraco | X20: =V20&W20 -> AltoFraco | Y20: Médio/Alto | Z20: Controle foi considerado inadequado. O exame poderá ser feito para confirmar consequências adversas da inadequação. | AA20: +Testes substantivos | AB20: Alta
V21: Alto | W21: =$N$6 -> Mediano | X21: =V21&W21 -> AltoMediano | Y21: Médio/Alto | Z21: Sua aplicação/efetividade pode ser testada, para verificar seu desempenho em relação aos objetivos pretendidos, ao mesmo tempo em que é preciso confirmar as consequencias adversas de seu funcionamento não ser o ideal. | AA21: Testes substantivos/Testes de Controles | AB21: Alta, dependerá do nível dos riscos que o controle pretende mitigar
V22: Alto | W22: =$N$5 -> Satisfatório | X22: =V22&W22 -> AltoSatisfatório | Y22: Médio | Z22: Controle foi considerado adequado na avaliação preliminar, mas sua aplicação/efetividade precisa ser testada, para verificar se está atingindo os objetivos pretendidos. | AA22: Testes substantivos/Testes de Controles | AB22: Baixa
V23: Alto | W23: =$N$4 -> Forte | X23: =V23&W23 -> AltoForte | Y23: Baixo/Médio | Z23: Controle foi considerado forte na avaliação preliminar, mas sua aplicação/efetividade precisa ser testada, para verificar se está atingindo os objetivos pretendidos. | AA23: Testes substantivos/Testes de Controles | AB23: Baixa
V24: Crítico | W24: =$N$8 -> Inexistente | X24: =V24&W24 -> CríticoInexistente | Y24: Extremo | Z24: Controle inexiste. O exame poderá ser feito para confirmar consequências adversas da inadequação ou ausência do controle. | AA24: Testes substantivos | AB24: Muito alta
V25: Crítico | W25: =$N$7 -> Fraco | X25: =V25&W25 -> CríticoFraco | Y25: Alto/Extremo | Z25: Controle foi considerado inadequado. O exame poderá ser feito para confirmar consequências adversas da inadequação. | AA25: +Testes substantivos | AB25: Muito alta
V26: Crítico | W26: =$N$6 -> Mediano | X26: =V26&W26 -> CríticoMediano | Y26: Alto | Z26: Sua aplicação/efetividade pode ser testada, para verificar seu desempenho em relação aos objetivos pretendidos, ao mesmo tempo em que é preciso confirmar as consequencias adversas de seu funcionamento não ser o ideal. | AA26: Testes substantivos/Testes de Controles | AB26: Muito alta
V27: Crítico | W27: =$N$5 -> Satisfatório | X27: =V27&W27 -> CríticoSatisfatório | Y27: Médio/Alto | Z27: Controle foi considerado adequado na avaliação preliminar, mas sua aplicação/efetividade precisa ser testada, para verificar se está atingindo os objetivos pretendidos. | AA27: Testes substantivos/Testes de Controles | AB27: Alta
V28: Crítico | W28: =$N$4 -> Forte | X28: =V28&W28 -> CríticoForte | Y28: Médio | Z28: Controle foi considerado forte na avaliação preliminar, mas sua aplicação/efetividade precisa ser testada, para verificar se está atingindo os objetivos pretendidos. | AA28: Testes substantivos/Testes de Controles | AB28: Alta

Sheet Orientações
C1: ORIENTAÇÕES
C2: Objeto da Auditoria | D2: É a informação, condição ou atividade que é mensurada ou avaliada de acordo com critérios definidos. Entende-se que o Objeto de Auditoria é apropriado quando é identificável, passível de avaliação ou mensuração consistente, apto a produzir evidência suficiente e adequada para fundamentar a opinião ou conclusão de auditoria.
C3: Objetivo do Objeto da Auditoria | D3: Identificar o objetivo do processo de negócio objeto de avaliação.
C4: Fluxo Descritivo - Mapeamento do Processo | D4: Identificar a representação de um processo de trabalho por meio de um diagrama contendo a sequência dos passos necessários à consecução de determinada atividade.
C5: Normativas Aplicáveis ao Processo | D5: Inserir as políticas, as normas, os procedimentos e os demais regulamentos aplicáveis ao processo de negócio sob análise.
C6: Entendimento do Objeto do Trabalho | D6: Descrever de forma sintética o entendimento do auditor, obtido após seu estudo dos elementos e informações relacionados ao objeto, tais como a relevância do objeto selecionado, fluxos de processos, sistemas envolvidos, a estrutura organizacional, os responsáveis, relatórios anteriores, organogramas, políticas e normativas que regulam o objeto, processos relacionados ao objeto, entre outros, de forma que um terceiro, ao ler o entendimento, tenha uma visão dos principais componentes do objeto e seu funcionamento.
C7: Questão de Auditoria | D7: Elemento que define o objetivo da auditoria e constitui a base da estrutura das análises que permitirão chegar à conclusão sobre os controles.
C8: Risco | D8: Possibilidade de ocorrência de um evento que tenha impacto no atingimento dos objetivos da organização. Técnicas de Identificação de riscos: - Brainstorming - Questionários - Entrevistas - Análise SWOT - Análise de dados históricos - Diagrama de causa e efeito - Opinião de especialistas
C9: Fonte do Risco | D9: Relacionar as Fontes do Risco.
C10: Possíveis Causas | D10: Consistem nas situações que dão origem aos riscos, podendo ser descritas por meio da conjugação de possíveis fontes e de vulnerabilidades a elas associadas.
C11: Possíveis Consequências | D11: Consistem nos resultados da materialização dos riscos que afetam os objetivos.
C12: Probabilidade | D12: Avaliar a probabilidade do risco com base nos critérios sugeridos na aba "Tabelas". Para estimar a probabilidade, considere que todos os controles falharam.
C13: Impacto | D13: Avaliar o impacto do risco com base nos critérios sugeridos na aba "Tabelas".
... C27: Resposta à Questão Geral de Auditoria | D27: Descrição para o resultado final do trabalho de auditoria.

Sheet Vulnerabilidades
B1: QUADRO DE VULNERABILIDADES
B2: Fontes Internas | J2: Fontes Externas | O2: Eventos
A3: Fontes Internas | B3: Pessoas | C3: Processos | D3: Sistemas | E3: Infraestrutura Física | F3: Tecnologia | G3: Governança | H3: Planejamento | I3: Fontes Externas | J3: Ambientais | K3: Econômicas | L3: Legais/jurídicas | O3: Cs 1.1 - | P3: Cs 1.2 - | Q3: Cs 1.3 - | R3: Cs 2.1 - | S3: Cs 2.2 - | T3: Cs 2.3 - | U3: Cs 3.1 - | V3: Cs 3.2 - | W3: Cs 3.3 - | X3: Cs 4.1 - | Y3: Cs 4.2 - | Z3: Cs 4.3 - | AA3: Cs 5.1 - | AB3: Cs 5.2 - | AC3: Cs 5.3 - | AD3: Cs 6.1 - | AE3: Cs 6.2 - | AF3: Cs 6.3 - | AG3: Cs 7.1 - | AH3: Cs 7.2 - | AI3: Cs 7.3 - | AJ3: Cs 8.1 - | AK3: Cs 8.2 - | AL3: Cs 8.3 - | AM3: Cs 9.1 - | AN3: Cs 9.2 - | AO3: Cs 9.3 -
B4: Alta rotatividade | C4: Deficiência em gerenciamento de contrato | D4: Baixo grau de automação | E4: Falha no controle de acesso físico | F4: Controles insuficientes sobre a transferência de dados. | G4: Centralização ou descentralização excessiva de responsabilidades | H4: Ausência de planejamento | J4: Epidemia | K4: Contingenciamento | L4: Ações judiciais | N4: 2 | O4: =HLOOKUP('Identificação e Análise'!$D$12,Vulnerabilidades!$A$3:$L$27,Vulnerabilidades!$N4,0) -> #N/A | P4: =HLOOKUP('Identificação e Análise'!#REF!,Vulnerabilidades!$A$3:$L$27,Vulnerabilidades!$N4,0) -> #REF! | Q4: =HLOOKUP('Identificação e Análise'!#REF!,Vulnerabilidades!$A$3:$L$27,Vulnerabilidades!$N4,0) -> #REF! | R4: =HLOOKUP('Identificação e Análise'!$D$15,Vulnerabilidades!$A$3:$L$27,Vulnerabilidades!$N4,0) -> #N/A | S4: =HLOOKUP('Identificação e Análise'!#REF!,Vulnerabilidades!$A$3:$L$27,Vulnerabilidades!$N4,0) -> #REF! | T4: =HLOOKUP('Identificação e Análise'!#REF!,Vulnerabilidades!$A$3:$L$27,Vulnerabilidades!$N4,0) -> #REF! | U4: =HLOOKUP('Identificação e Análise'!$D$18,Vulnerabilidades!$A$3:$L$27,Vulnerabilidades!$N4,0) -> #N/A | V4: =HLOOKUP('Identificação e Análise'!#REF!,Vulnerabilidades!$A$3:$L$27,Vulnerabilidades!$N4,0) -> #REF! | W4: =HLOOKUP('Identificação e Análise'!#REF!,Vulnerabilidades!$A$3:$L$27,Vulnerabilidades!$N4,0) -> #REF! | X4: =HLOOKUP('Identificação e Análise'!$D$21,Vulnerabilidades!$A$3:$L$27,Vulnerabilidades!$N4,0) -> #N/A | Y4: =HLOOKUP('Identificação e Análise'!#REF!,Vulnerabilidades!$A$3:$L$27,Vulnerabilidades!$N4,0) -> #REF! | Z4: =HLOOKUP('Identificação e Análise'!#REF!,Vulnerabilidades!$A$3:$L$27,Vulnerabilidades!$N4,0) -> #REF! | AA4: =HLOOKUP('Identificação e Análise'!$D$24,Vulnerabilidades!$A$3:$L$27,Vulnerabilidades!$N4,0) -> #N/A | AB4: =HLOOKUP('Identificação e Análise'!#REF!,Vulnerabilidades!$A$3:$L$27,Vulnerabilidades!$N4,0) -> #REF! | AC4: =HLOOKUP('Identificação e Análise'!#REF!,Vulnerabilidades!$A$3:$L$27,Vulnerabilidades!$N4,0) -> #REF! | AD4: =HLOOKUP('Identificação e Análise'!$D$27,Vulnerabilidades!$A$3:$L$27,Vulnerabilidades!$N4,0) -> #N/A | AE4: =HLOOKUP('Identificação e Análise'!#REF!,Vulnerabilidades!$A$3:$L$27,Vulnerabilidades!$N4,0) -> #REF! | AF4: =HLOOKUP('Identificação e Análise'!#REF!,Vulnerabilidades!$A$3:$L$27,Vulnerabilidades!$N4,0) -> #REF! | AG4: =HLOOKUP('Identificação e Análise'!$D$30,Vulnerabilidades!$A$3:$L$27,Vulnerabilidades!$N4,0) -> #N/A | AH4: =HLOOKUP('Identificação e Análise'!#REF!,Vulnerabilidades!$A$3:$L$27,Vulnerabilidades!$N4,0) -> #REF! | AI4: =HLOOKUP('Identificação e Análise'!#REF!,Vulnerabilidades!$A$3:$L$27,Vulnerabilidades!$N4,0) -> #REF! | AJ4: =HLOOKUP('Identificação e Análise'!$D$33,Vulnerabilidades!$A$3:$L$27,Vulnerabilidades!$N4,0) -> #N/A | AK4: =HLOOKUP('Identificação e Análise'!#REF!,Vulnerabilidades!$A$3:$L$27,Vulnerabilidades!$N4,0) -> #REF! | AL4: =HLOOKUP('Identificação e Análise'!#REF!,Vulnerabilidades!$A$3:$L$27,Vulnerabilidades!$N4,0) -> #REF! | AM4: =HLOOKUP('Identificação e Análise'!$D$36,Vulnerabilidades!$A$3:$L$27,Vulnerabilidades!$N4,0) -> #N/A | AN4: =HLOOKUP('Identificação e Análise'!#REF!,Vulnerabilidades!$A$3:$L$27,Vulnerabilidades!$N4,0) -> #REF! | AO4: =HLOOKUP('Identificação e Análise'!#REF!,Vulnerabilidades!$A$3:$L$27,Vulnerabilidades!$N4,0) -> #REF!
B5: Descumprimento de norma interna | C5: Falha na concepção do processo (Falha de Desenho do Processo) | D5: Falha nos procedimentos de teste ou homologação de sistemas | E5: Falha ou deficiência na localização da infraestrutura | F5: Falha ou deficiência nos dispositivos de backup | G5: Competências e responsabilidades não identificadas ou desrespeitadas | H5: Planejamento elaborado sem embasamento técnico | J5: Incêndio | K5: Crise de credibilidade | L5: Alterações na jurisprudência de tribunais | N5: 3 | O5: =HLOOKUP('Identificação e Análise'!$D$12,Vulnerabilidades!$A$3:$L$27,Vulnerabilidades!$N5,0) -> #N/A | P5: =HLOOKUP('Identificação e Análise'!#REF!,Vulnerabilidades!$A$3:$L$27,Vulnerabilidades!$N5,0) -> #REF! | Q5: =HLOOKUP('Identificação e Análise'!#REF!,Vulnerabilidades!$A$3:$L$27,Vulnerabilidades!$N5,0) -> #REF! | R5: =HLOOKUP('Identificação e Análise'!$D$15,Vulnerabilidades!$A$3:$L$27,Vulnerabilidades!$N5,0) -> #N/A | S5: =HLOOKUP('Identificação e Análise'!#REF!,Vulnerabilidades!$A$3:$L$27,Vulnerabilidades!$N5,0) -> #REF! | T5: =HLOOKUP('Identificação e Análise'!#REF!,Vulnerabilidades!$A$3:$L$27,Vulnerabilidades!$N5,0) -> #REF! | U5: =HLOOKUP('Identificação e Análise'!$D$18,Vulnerabilidades!$A$3:$L$27,Vulnerabilidades!$N5,0) -> #N/A | V5: =HLOOKUP('Identificação e Análise'!#REF!,Vulnerabilidades!$A$3:$L$27,Vulnerabilidades!$N5,0) -> #REF! | W5: =HLOOKUP('Identificação e Análise'!#REF!,Vulnerabilidades!$A$3:$L$27,Vulnerabilidades!$N5,0) -> #REF! | X5: =HLOOKUP('Identificação e Análise'!$D$21,Vulnerabilidades!$A$3:$L$27,Vulnerabilidades!$N5,0) -> #N/A | Y5: =HLOOKUP('Identificação e Análise'!#REF!,Vulnerabilidades!$A$3:$L$27,Vulnerabilidades!$N5,0) -> #REF! | Z5: =HLOOKUP('Identificação e Análise'!#REF!,Vulnerabilidades!$A$3:$L$27,Vulnerabilidades!$N5,0) -> #REF! | AA5: =HLOOKUP('Identificação e Análise'!$D$24,Vulnerabilidades!$A$3:$L$27,Vulnerabilidades!$N5,0) -> #N/A | AB5: =HLOOKUP('Identificação e Análise'!#REF!,Vulnerabilidades!$A$3:$L$27,Vulnerabilidades!$N5,0) -> #REF! | AC5: =HLOOKUP('Identificação e Análise'!#REF!,Vulnerabilidades!$A$3:$L$27,Vulnerabilidades!$N5,0) -> #REF! | AD5: =HLOOKUP('Identificação e Análise'!$D$27,Vulnerabilidades!$A$3:$L$27,Vulnerabilidades!$N5,0) -> #N/A | AE5: =HLOOKUP('Identificação e Análise'!#REF!,Vulnerabilidades!$A$3:$L$27,Vulnerabilidades!$N5,0) -> #REF! | AF5: =HLOOKUP('Identificação e Análise'!#REF!,Vulnerabilidades!$A$3:$L$27,Vulnerabilidades!$N5,0) -> #REF! | AG5: =HLOOKUP('Identificação e Análise'!$D$30,Vulnerabilidades!$A$3:$L$27,Vulnerabilidades!$N5,0) -> #N/A | AH5: =HLOOKUP('Identificação e Análise'!#REF!,Vulnerabilidades!$A$3:$L$27,Vulnerabilidades!$N5,0) -> #REF! | AI5: =HLOOKUP('Identificação e Análise'!#REF!,Vulnerabilidades!$A$3:$L$27,Vulnerabilidades!$N5,0) -> #REF! | AJ5: =HLOOKUP('Identificação e Análise'!$D$33,Vulnerabilidades!$A$3:$L$27,Vulnerabilidades!$N5,0) -> #N/A | AK5: =HLOOKUP('Identificação e Análise'!#REF!,Vulnerabilidades!$A$3:$L$27,Vulnerabilidades!$N5,0) -> #REF! | AL5: =HLOOKUP('Identificação e Análise'!#REF!,Vulnerabilidades!$A$3:$L$27,Vulnerabilidades!$N5,0) -> #REF! | AM5: =HLOOKUP('Identificação e Análise'!$D$36,Vulnerabilidades!$A$3:$L$27,Vulnerabilidades!$N5,0) -> #N/A | AN5: =HLOOKUP('Identificação e Análise'!#REF!,Vulnerabilidades!$A$3:$L$27,Vulnerabilidades!$N5,0) -> #REF! | AO5: =HLOOKUP('Identificação e Análise'!#REF!,Vulnerabilidades!$A$3:$L$27,Vulnerabilidades!$N5,0) -> #REF!
B6: Descumprimento de norma legal | C6: Falha na gestão e fiscalização de contratos e convênios | D6: Falta ou ineficiência de sistema informatizado operacional ou de controle | E6: Falha ou deficiência nas instalações | F6: Falta de investimento em TI | G6: Deficiência em gerenciamento de contrato | H6: Planejamento em desacordo com a realidade | J6: Inundação | K6: Elevação ou redução da carga tributária | L6: Novas leis e normas reguladoras | N6: 4 | O6: =HLOOKUP('Identificação e Análise'!$D$12,Vulnerabilidades!$A$3:$L$27,Vulnerabilidades!$N6,0) -> #N/A | P6: =HLOOKUP('Identificação e Análise'!#REF!,Vulnerabilidades!$A$3:$L$27,Vulnerabilidades!$N6,0) -> #REF! | Q6: =HLOOKUP('Identificação e Análise'!#REF!,Vulnerabilidades!$A$3:$L$27,Vulnerabilidades!$N6,0) -> #REF! | R6: =HLOOKUP('Identificação e Análise'!$D$15,Vulnerabilidades!$A$3:$L$27,Vulnerabilidades!$N6,0) -> #N/A | S6: =HLOOKUP('Identificação e Análise'!#REF!,Vulnerabilidades!$A$3:$L$27,Vulnerabilidades!$N6,0) -> #REF! | T6: =HLOOKUP('Identificação e Análise'!#REF!,Vulnerabilidades!$A$3:$L$27,Vulnerabilidades!$N6,0) -> #REF! | U6: =HLOOKUP('Identificação e Análise'!$D$18,Vulnerabilidades!$A$3:$L$27,Vulnerabilidades!$N6,0) -> #N/A | V6: =HLOOKUP('Identificação e Análise'!#REF!,Vulnerabilidades!$A$3:$L$27,Vulnerabilidades!$N6,0) -> #REF! | W6: =HLOOKUP('Identificação e Análise'!#REF!,Vulnerabilidades!$A$3:$L$27,Vulnerabilidades!$N6,0) -> #REF! | X6: =HLOOKUP('Identificação e Análise'!$D$21,Vulnerabilidades!$A$3:$L$27,Vulnerabilidades!$N6,0) -> #N/A | Y6: =HLOOKUP('Identificação e Análise'!#REF!,Vulnerabilidades!$A$3:$L$27,Vulnerabilidades!$N6,0) -> #REF! | Z6: =HLOOKUP('Identificação e Análise'!#REF!,Vulnerabilidades!$A$3:$L$27,Vulnerabilidades!$N6,0) -> #REF! | AA6: =HLOOKUP('Identificação e Análise'!$D$24,Vulnerabilidades!$A$3:$L$27,Vulnerabilidades!$N6,0) -> #N/A | AB6: =HLOOKUP('Identificação e Análise'!#REF!,Vulnerabilidades!$A$3:$L$27,Vulnerabilidades!$N6,0) -> #REF! | AC6: =HLOOKUP('Identificação e Análise'!#REF!,Vulnerabilidades!$A$3:$L$27,Vulnerabilidades!$N6,0) -> #REF! | AD6: =HLOOKUP('Identificação e Análise'!$D$27,Vulnerabilidades!$A$3:$L$27,Vulnerabilidades!$N6,0) -> #N/A | AE6: =HLOOKUP('Identificação e Análise'!#REF!,Vulnerabilidades!$A$3:$L$27,Vulnerabilidades!$N6,0) -> #REF! | AF6: =HLOOKUP('Identificação e Análise'!#REF!,Vulnerabilidades!$A$3:$L$27,Vulnerabilidades!$N6,0) -> #REF! | AG6: =HLOOKUP('Identificação e Análise'!$D$30,Vulnerabilidades!$A$3:$L$27,Vulnerabilidades!$N6,0) -> #N/A | AH6: =HLOOKUP('Identificação e Análise'!#REF!,Vulnerabilidades!$A$3:$L$27,Vulnerabilidades!$N6,0) -> #REF! | AI6: =HLOOKUP('Identificação e Análise'!#REF!,Vulnerabilidades!$A$3:$L$27,Vulnerabilidades!$N6,0) -> #REF! | AJ6: =HLOOKUP('Identificação e Análise'!$D$33,Vulnerabilidades!$A$3:$L$27,Vulnerabilidades!$N6,0) -> #N/A | AK6: =HLOOKUP('Identificação e Análise'!#REF!,Vulnerabilidades!$A$3:$L$27,Vulnerabilidades!$N6,0) -> #REF! | AL6: =HLOOKUP('Identificação e Análise'!#REF!,Vulnerabilidades!$A$3:$L$27,Vulnerabilidades!$N6,0) -> #REF! | AM6: =HLOOKUP('Identificação e Análise'!$D$36,Vulnerabilidades!$A$3:$L$27,Vulnerabilidades!$N6,0) -> #N/A | AN6: =HLOOKUP('Identificação e Análise'!#REF!,Vulnerabilidades!$A$3:$L$27,Vulnerabilidades!$N6,0) -> #REF! | AO6: =HLOOKUP('Identificação e Análise'!#REF!,Vulnerabilidades!$A$3:$L$27,Vulnerabilidades!$N6,0) -> #REF!
B7: Desmotivadas | C7: Falha nos processos de avaliação de proponentes | D7: Inexistência de controles de acesso lógico/backups | E7: Inexistência de controles de acesso físico. | F7: Falta ou falha de integração entre sistemas | G7: Deficiência na estrutura de controles internos | H7: Planejamento em desacordo com as normas vigentes | J7: Mudança climática brusca | K7: Oscilações de juros, de câmbio e de preços | L7: Novos regulamentos | N7: 5 | O7: =HLOOKUP('Identificação e Análise'!$D$12,Vulnerabilidades!$A$3:$L$27,Vulnerabilidades!$N7,0) -> #N/A | P7: =HLOOKUP('Identificação e Análise'!#REF!,Vulnerabilidades!$A$3:$L$27,Vulnerabilidades!$N7,0) -> #REF! | Q7: =HLOOKUP('Identificação e Análise'!#REF!,Vulnerabilidades!$A$3:$L$27,Vulnerabilidades!$N7,0) -> #REF! | R7: =HLOOKUP('Identificação e Análise'!$D$15,Vulnerabilidades!$A$3:$L$27,Vulnerabilidades!$N7,0) -> #N/A | S7: =HLOOKUP('Identificação e Análise'!#REF!,Vulnerabilidades!$A$3:$L$27,Vulnerabilidades!$N7,0) -> #REF! | T7: =HLOOKUP('Identificação e Análise'!#REF!,Vulnerabilidades!$A$3:$L$27,Vulnerabilidades!$N7,0) -> #REF! | U7: =HLOOKUP('Identificação e Análise'!$D$18,Vulnerabilidades!$A$3:$L$27,Vulnerabilidades!$N7,0) -> #N/A | V7: =HLOOKUP('Identificação e Análise'!#REF!,Vulnerabilidades!$A$3:$L$27,Vulnerabilidades!$N7,0) -> #REF! | W7: =HLOOKUP('Identificação e Análise'!#REF!,Vulnerabilidades!$A$3:$L$27,Vulnerabilidades!$N7,0) -> #REF! | X7: =HLOOKUP('Identificação e Análise'!$D$21,Vulnerabilidades!$A$3:$L$27,Vulnerabilidades!$N7,0) -> #N/A | Y7: =HLOOKUP('Identificação e Análise'!#REF!,Vulnerabilidades!$A$3:$L$27,Vulnerabilidades!$N7,0) -> #REF! | Z7: =HLOOKUP('Identificação e Análise'!#REF!,Vulnerabilidades!$A$3:$L$27,Vulnerabilidades!$N7,0) -> #REF! | AA7: =HLOOKUP('Identificação e Análise'!$D$24,Vulnerabilidades!$A$3:$L$27,Vulnerabilidades!$N7,0) -> #N/A | AB7: =HLOOKUP('Identificação e Análise'!#REF!,Vulnerabilidades!$A$3:$L$27,Vulnerabilidades!$N7,0) -> #REF! | AC7: =HLOOKUP('Identificação e Análise'!#REF!,Vulnerabilidades!$A$3:$L$27,Vulnerabilidades!$N7,0) -> #REF! | AD7: =HLOOKUP('Identificação e Análise'!$D$27,Vulnerabilidades!$A$3:$L$27,Vulnerabilidades!$N7,0) -> #N/A | AE7: =HLOOKUP('Identificação e Análise'!#REF!,Vulnerabilidades!$A$3:$L$27,Vulnerabilidades!$N7,0) -> #REF! | AF7: =HLOOKUP('Identificação e Análise'!#REF!,Vulnerabilidades!$A$3:$L$27,Vulnerabilidades!$N7,0) -> #REF! | AG7: =HLOOKUP('Identificação e Análise'!$D$30,Vulnerabilidades!$A$3:$L$27,Vulnerabilidades!$N7,0) -> #N/A | AH7: =HLOOKUP('Identificação e Análise'!#REF!,Vulnerabilidades!$A$3:$L$27,Vulnerabilidades!$N7,0) -> #REF! | AI7: =HLOOKUP('Identificação e Análise'!#REF!,Vulnerabilidades!$A$3:$L$27,Vulnerabilidades!$N7,0) -> #REF! | AJ7: =HLOOKUP('Identificação e Análise'!$D$33,Vulnerabilidades!$A$3:$L$27,Vulnerabilidades!$N7,0) -> #N/A | AK7: =HLOOKUP('Identificação e Análise'!#REF!,Vulnerabilidades!$A$3:$L$27,Vulnerabilidades!$N7,0) -> #REF! | AL7: =HLOOKUP('Identificação e Análise'!#REF!,Vulnerabilidades!$A$3:$L$27,Vulnerabilidades!$N7,0) -> #REF! | AM7: =HLOOKUP('Identificação e Análise'!$D$36,Vulnerabilidades!$A$3:$L$27,Vulnerabilidades!$N7,0) -> #N/A | AN7: =HLOOKUP('Identificação e Análise'!#REF!,Vulnerabilidades!$A$3:$L$27,Vulnerabilidades!$N7,0) -> #REF! | AO7: =HLOOKUP('Identificação e Análise'!#REF!,Vulnerabilidades!$A$3:$L$27,Vulnerabilidades!$N7,0) -> #REF!
B8: Desvios éticos | C8: Falha operacional / Erro de execução | D8: Obsoletos | E8: Instalações ou leiaute inadequados | F8: Processo produtivo sem proteção contra espionagem | G8: Deficiência nos fluxos de informação e comunicação | H8: Planejamentocom objetivos e estratégias inadequados | K8: Queda de arrecadação | N8: 6 | O8: =HLOOKUP('Identificação e Análise'!$D$12,Vulnerabilidades!$A$3:$L$27,Vulnerabilidades!$N8,0) -> #N/A | P8: =HLOOKUP('Identificação e Análise'!#REF!,Vulnerabilidades!$A$3:$L$27,Vulnerabilidades!$N8,0) -> #REF! | Q8: =HLOOKUP('Identificação e Análise'!#REF!,Vulnerabilidades!$A$3:$L$27,Vulnerabilidades!$N8,0) -> #REF! | R8: =HLOOKUP('Identificação e Análise'!$D$15,Vulnerabilidades!$A$3:$L$27,Vulnerabilidades!$N8,0) -> #N/A | S8: =HLOOKUP('Identificação e Análise'!#REF!,Vulnerabilidades!$A$3:$L$27,Vulnerabilidades!$N8,0) -> #REF! | T8: =HLOOKUP('Identificação e Análise'!#REF!,Vulnerabilidades!$A$3:$L$27,Vulnerabilidades!$N8,0) -> #REF! | U8: =HLOOKUP('Identificação e Análise'!$D$18,Vulnerabilidades!$A$3:$L$27,Vulnerabilidades!$N8,0) -> #N/A | V8: =HLOOKUP('Identificação e Análise'!#REF!,Vulnerabilidades!$A$3:$L$27,Vulnerabilidades!$N8,0) -> #REF! | W8: =HLOOKUP('Identificação e Análise'!#REF!,Vulnerabilidades!$A$3:$L$27,Vulnerabilidades!$N8,0) -> #REF! | X8: =HLOOKUP('Identificação e Análise'!$D$21,Vulnerabilidades!$A$3:$L$27,Vulnerabilidades!$N8,0) -> #N/A | Y8: =HLOOKUP('Identificação e Análise'!#REF!,Vulnerabilidades!$A$3:$L$27,Vulnerabilidades!$N8,0) -> #REF! | Z8: =HLOOKUP('Identificação e Análise'!#REF!,Vulnerabilidades!$A$3:$L$27,Vulnerabilidades!$N8,0) -> #REF! | AA8: =HLOOKUP('Identificação e Análise'!$D$24,Vulnerabilidades!$A$3:$L$27,Vulnerabilidades!$N8,0) -> #N/A | AB8: =HLOOKUP('Identificação e Análise'!#REF!,Vulnerabilidades!$A$3:$L$27,Vulnerabilidades!$N8,0) -> #REF! | AC8: =HLOOKUP('Identificação e Análise'!#REF!,Vulnerabilidades!$A$3:$L$27,Vulnerabilidades!$N8,0) -> #REF! | AD8: =HLOOKUP('Identificação e Análise'!$D$27,Vulnerabilidades!$A$3:$L$27,Vulnerabilidades!$N8,0) -> #N/A | AE8: =HLOOKUP('Identificação e Análise'!#REF!,Vulnerabilidades!$A$3:$L$27,Vulnerabilidades!$N8,0) -> #REF! | AF8: =HLOOKUP('Identificação e Análise'!#REF!,Vulnerabilidades!$A$3:$L$27,Vulnerabilidades!$N8,0) -> #REF! | AG8: =HLOOKUP('Identificação e Análise'!$D$30,Vulnerabilidades!$A$3:$L$27,Vulnerabilidades!$N8,0) -> #N/A | AH8: =HLOOKUP('Identificação e Análise'!#REF!,Vulnerabilidades!$A$3:$L$27,Vulnerabilidades!$N8,0) -> #REF! | AI8: =HLOOKUP('Identificação e Análise'!#REF!,Vulnerabilidades!$A$3:$L$27,Vulnerabilidades!$N8,0) -> #REF! | AJ8: =HLOOKUP('Identificação e Análise'!$D$33,Vulnerabilidades!$A$3:$L$27,Vulnerabilidades!$N8,0) -> #N/A | AK8: =HLOOKUP('Identificação e Análise'!#REF!,Vulnerabilidades!$A$3:$L$27,Vulnerabilidades!$N8,0) -> #REF! | AL8: =HLOOKUP('Identificação e Análise'!#REF!,Vulnerabilidades!$A$3:$L$27,Vulnerabilidades!$N8,0) -> #REF! | AM8: =HLOOKUP('Identificação e Análise'!$D$36,Vulnerabilidades!$A$3:$L$27,Vulnerabilidades!$N8,0) -> #N/A | AN8: =HLOOKUP('Identificação e Análise'!#REF!,Vulnerabilidades!$A$3:$L$27,Vulnerabilidades!$N8,0) -> #REF! | AO8: =HLOOKUP('Identificação e Análise'!#REF!,Vulnerabilidades!$A$3:$L$27,Vulnerabilidades!$N8,0) -> #REF!
